root - INFO - Бот запускается
telegram.ext.updater - INFO - Received signal 2 (SIGINT), stopping...
2018-12-27 13:06:06,263 - INFO - Бот запускается
2018-12-27 13:06:25,421 - INFO - User: dm_zakharov, Chat id: 435920381, Message: /start
2018-12-27 13:07:39,380 - INFO - Received signal 2 (SIGINT), stopping...
2018-12-27 17:54:32,684 - INFO - Бот запускается
2018-12-27 17:54:58,161 - INFO - using lxml
2018-12-27 17:55:00,373 - INFO - using lxml html builder
2018-12-27 17:55:02,663 - INFO - using lxml html builder
2018-12-27 17:55:04,343 - INFO - using lxml html builder
2018-12-27 17:55:38,246 - INFO - Received signal 2 (SIGINT), stopping...
2018-12-27 17:57:30,559 - INFO - Бот запускается
2018-12-27 17:57:38,171 - INFO - User: dm_zakharov, Chat id: 435920381, Message: Поиск фильма
2018-12-27 17:57:49,674 - INFO - using lxml
2018-12-27 17:57:51,206 - INFO - using lxml html builder
2018-12-27 17:57:54,227 - INFO - using lxml html builder
2018-12-27 17:57:56,070 - INFO - using lxml html builder
2018-12-27 17:57:56,115 - INFO - User: dm_zakharov, Chat id: 435920381, Message: Matrix
2018-12-27 17:58:03,507 - INFO - User: dm_zakharov, Chat id: 435920381, Message: Отмена
2018-12-27 17:58:10,788 - INFO - User: dm_zakharov, Chat id: 435920381, Message: Поиск актера
2018-12-27 17:58:19,760 - INFO - using lxml html builder
2018-12-27 17:58:21,753 - INFO - using lxml html builder
2018-12-27 17:58:23,674 - INFO - using lxml html builder
2018-12-27 17:58:23,857 - INFO - User: dm_zakharov, Chat id: 435920381, Message: Mel Gibson
2018-12-27 17:58:31,553 - INFO - User: dm_zakharov, Chat id: 435920381, Message: Отмена
2018-12-27 17:59:02,599 - INFO - Received signal 2 (SIGINT), stopping...
2018-12-27 20:36:18,211 - INFO - Бот запускается
2018-12-27 20:37:22,430 - INFO - Бот запускается
2019-01-05 20:44:25,245 - INFO - Бот запускается
2019-01-05 20:44:28,241 - ERROR - An uncaught error was raised while processing the update
Traceback (most recent call last):
  File "C:\projects\Movie_bot\env\lib\site-packages\telegram\ext\dispatcher.py", line 279, in process_update
    handler.handle_update(update, self)
  File "C:\projects\Movie_bot\env\lib\site-packages\telegram\ext\conversationhandler.py", line 305, in handle_update
    new_state = self.current_handler.handle_update(update, dispatcher)
  File "C:\projects\Movie_bot\env\lib\site-packages\telegram\ext\commandhandler.py", line 173, in handle_update
    return self.callback(dispatcher.bot, update, **optional_args)
  File "C:\projects\Movie_bot\movie_bot.py", line 36, in greet_user
    ['Отмена']])
TypeError: list indices must be integers or slices, not str
2019-01-05 20:45:11,103 - WARNING - Retrying (Retry(total=2, connect=None, read=None, redirect=None)) after connection broken by 'ConnectTimeoutError(<telegram.vendor.ptb_urllib3.urllib3.contrib.socks.SOCKSHTTPSConnection object at 0x0000007671D61080>, 'Connection to api.telegram.org timed out. (connect timeout=5.0)')': /bot689046366:AAFcTW-HmpAkxuTb4a5cOw_sQpdy0XqOxCk/getUpdates
2019-01-05 20:45:16,129 - WARNING - Retrying (Retry(total=1, connect=None, read=None, redirect=None)) after connection broken by 'ConnectTimeoutError(<telegram.vendor.ptb_urllib3.urllib3.contrib.socks.SOCKSHTTPSConnection object at 0x0000007671D3BCC0>, 'Connection to api.telegram.org timed out. (connect timeout=5.0)')': /bot689046366:AAFcTW-HmpAkxuTb4a5cOw_sQpdy0XqOxCk/getUpdates
2019-01-05 20:45:21,132 - WARNING - Retrying (Retry(total=0, connect=None, read=None, redirect=None)) after connection broken by 'ConnectTimeoutError(<telegram.vendor.ptb_urllib3.urllib3.contrib.socks.SOCKSHTTPSConnection object at 0x0000007671D3BE10>, 'Connection to api.telegram.org timed out. (connect timeout=5.0)')': /bot689046366:AAFcTW-HmpAkxuTb4a5cOw_sQpdy0XqOxCk/getUpdates
2019-01-05 20:45:26,136 - ERROR - Error while getting Updates: urllib3 HTTPError SOCKSHTTPSConnectionPool(host='api.telegram.org', port=443): Max retries exceeded with url: /bot689046366:AAFcTW-HmpAkxuTb4a5cOw_sQpdy0XqOxCk/getUpdates (Caused by ConnectTimeoutError(<telegram.vendor.ptb_urllib3.urllib3.contrib.socks.SOCKSHTTPSConnection object at 0x0000007671D3BF28>, 'Connection to api.telegram.org timed out. (connect timeout=5.0)'))
2019-01-05 20:45:26,136 - ERROR - No error handlers are registered, logging exception.
Traceback (most recent call last):
  File "C:\projects\Movie_bot\env\lib\site-packages\socks.py", line 832, in connect
    super(socksocket, self).connect(proxy_addr)
socket.timeout: timed out

During handling of the above exception, another exception occurred:

Traceback (most recent call last):
  File "C:\projects\Movie_bot\env\lib\site-packages\telegram\vendor\ptb_urllib3\urllib3\contrib\socks.py", line 88, in _new_conn
    **extra_kw
  File "C:\projects\Movie_bot\env\lib\site-packages\socks.py", line 262, in create_connection
    raise err
  File "C:\projects\Movie_bot\env\lib\site-packages\socks.py", line 252, in create_connection
    sock.connect((remote_host, remote_port))
  File "C:\projects\Movie_bot\env\lib\site-packages\socks.py", line 100, in wrapper
    return function(*args, **kwargs)
  File "C:\projects\Movie_bot\env\lib\site-packages\socks.py", line 844, in connect
    raise ProxyConnectionError(msg, error)
socks.ProxyConnectionError: Error connecting to SOCKS5 proxy t1.learn.python.ru:1080: timed out

During handling of the above exception, another exception occurred:

Traceback (most recent call last):
  File "C:\projects\Movie_bot\env\lib\site-packages\telegram\vendor\ptb_urllib3\urllib3\connectionpool.py", line 617, in urlopen
    chunked=chunked)
  File "C:\projects\Movie_bot\env\lib\site-packages\telegram\vendor\ptb_urllib3\urllib3\connectionpool.py", line 360, in _make_request
    self._validate_conn(conn)
  File "C:\projects\Movie_bot\env\lib\site-packages\telegram\vendor\ptb_urllib3\urllib3\connectionpool.py", line 857, in _validate_conn
    super(HTTPSConnectionPool, self)._validate_conn(conn)
  File "C:\projects\Movie_bot\env\lib\site-packages\telegram\vendor\ptb_urllib3\urllib3\connectionpool.py", line 289, in _validate_conn
    conn.connect()
  File "C:\projects\Movie_bot\env\lib\site-packages\telegram\vendor\ptb_urllib3\urllib3\connection.py", line 284, in connect
    conn = self._new_conn()
  File "C:\projects\Movie_bot\env\lib\site-packages\telegram\vendor\ptb_urllib3\urllib3\contrib\socks.py", line 105, in _new_conn
    (self.host, self.timeout)
telegram.vendor.ptb_urllib3.urllib3.exceptions.ConnectTimeoutError: (<telegram.vendor.ptb_urllib3.urllib3.contrib.socks.SOCKSHTTPSConnection object at 0x0000007671D3BF28>, 'Connection to api.telegram.org timed out. (connect timeout=5.0)')

During handling of the above exception, another exception occurred:

Traceback (most recent call last):
  File "C:\projects\Movie_bot\env\lib\site-packages\telegram\utils\request.py", line 203, in _request_wrapper
    resp = self._con_pool.request(*args, **kwargs)
  File "C:\projects\Movie_bot\env\lib\site-packages\telegram\vendor\ptb_urllib3\urllib3\request.py", line 70, in request
    **urlopen_kw)
  File "C:\projects\Movie_bot\env\lib\site-packages\telegram\vendor\ptb_urllib3\urllib3\request.py", line 148, in request_encode_body
    return self.urlopen(method, url, **extra_kw)
  File "C:\projects\Movie_bot\env\lib\site-packages\telegram\vendor\ptb_urllib3\urllib3\poolmanager.py", line 244, in urlopen
    response = conn.urlopen(method, u.request_uri, **kw)
  File "C:\projects\Movie_bot\env\lib\site-packages\telegram\vendor\ptb_urllib3\urllib3\connectionpool.py", line 695, in urlopen
    **response_kw)
  File "C:\projects\Movie_bot\env\lib\site-packages\telegram\vendor\ptb_urllib3\urllib3\connectionpool.py", line 695, in urlopen
    **response_kw)
  File "C:\projects\Movie_bot\env\lib\site-packages\telegram\vendor\ptb_urllib3\urllib3\connectionpool.py", line 695, in urlopen
    **response_kw)
  File "C:\projects\Movie_bot\env\lib\site-packages\telegram\vendor\ptb_urllib3\urllib3\connectionpool.py", line 666, in urlopen
    _stacktrace=sys.exc_info()[2])
  File "C:\projects\Movie_bot\env\lib\site-packages\telegram\vendor\ptb_urllib3\urllib3\util\retry.py", line 376, in increment
    raise MaxRetryError(_pool, url, error or ResponseError(cause))
telegram.vendor.ptb_urllib3.urllib3.exceptions.MaxRetryError: SOCKSHTTPSConnectionPool(host='api.telegram.org', port=443): Max retries exceeded with url: /bot689046366:AAFcTW-HmpAkxuTb4a5cOw_sQpdy0XqOxCk/getUpdates (Caused by ConnectTimeoutError(<telegram.vendor.ptb_urllib3.urllib3.contrib.socks.SOCKSHTTPSConnection object at 0x0000007671D3BF28>, 'Connection to api.telegram.org timed out. (connect timeout=5.0)'))

During handling of the above exception, another exception occurred:

Traceback (most recent call last):
  File "C:\projects\Movie_bot\env\lib\site-packages\telegram\ext\updater.py", line 319, in _network_loop_retry
    if not action_cb():
  File "C:\projects\Movie_bot\env\lib\site-packages\telegram\ext\updater.py", line 280, in polling_action_cb
    allowed_updates=allowed_updates)
  File "C:\projects\Movie_bot\env\lib\site-packages\telegram\bot.py", line 65, in decorator
    result = func(self, *args, **kwargs)
  File "C:\projects\Movie_bot\env\lib\site-packages\telegram\bot.py", line 1975, in get_updates
    result = self._request.post(url, data, timeout=float(read_latency) + float(timeout))
  File "C:\projects\Movie_bot\env\lib\site-packages\telegram\utils\request.py", line 309, in post
    headers={'Content-Type': 'application/json'})
  File "C:\projects\Movie_bot\env\lib\site-packages\telegram\utils\request.py", line 209, in _request_wrapper
    raise NetworkError('urllib3 HTTPError {0}'.format(error))
telegram.error.NetworkError: urllib3 HTTPError SOCKSHTTPSConnectionPool(host='api.telegram.org', port=443): Max retries exceeded with url: /bot689046366:AAFcTW-HmpAkxuTb4a5cOw_sQpdy0XqOxCk/getUpdates (Caused by ConnectTimeoutError(<telegram.vendor.ptb_urllib3.urllib3.contrib.socks.SOCKSHTTPSConnection object at 0x0000007671D3BF28>, 'Connection to api.telegram.org timed out. (connect timeout=5.0)'))
2019-01-05 20:45:27,869 - ERROR - An uncaught error was raised while processing the update
Traceback (most recent call last):
  File "C:\projects\Movie_bot\env\lib\site-packages\telegram\ext\dispatcher.py", line 279, in process_update
    handler.handle_update(update, self)
  File "C:\projects\Movie_bot\env\lib\site-packages\telegram\ext\conversationhandler.py", line 305, in handle_update
    new_state = self.current_handler.handle_update(update, dispatcher)
  File "C:\projects\Movie_bot\env\lib\site-packages\telegram\ext\commandhandler.py", line 173, in handle_update
    return self.callback(dispatcher.bot, update, **optional_args)
  File "C:\projects\Movie_bot\movie_bot.py", line 36, in greet_user
    ['Отмена']])
TypeError: list indices must be integers or slices, not str
2019-01-05 20:52:30,638 - INFO - Received signal 2 (SIGINT), stopping...
2019-01-05 20:52:44,267 - INFO - Бот запускается
2019-01-05 20:52:51,642 - ERROR - An uncaught error was raised while processing the update
Traceback (most recent call last):
  File "C:\projects\Movie_bot\env\lib\site-packages\telegram\ext\dispatcher.py", line 279, in process_update
    handler.handle_update(update, self)
  File "C:\projects\Movie_bot\env\lib\site-packages\telegram\ext\conversationhandler.py", line 305, in handle_update
    new_state = self.current_handler.handle_update(update, dispatcher)
  File "C:\projects\Movie_bot\env\lib\site-packages\telegram\ext\commandhandler.py", line 173, in handle_update
    return self.callback(dispatcher.bot, update, **optional_args)
  File "C:\projects\Movie_bot\movie_bot.py", line 36, in greet_user
    ['Отмена']
TypeError: list indices must be integers or slices, not str
2019-01-05 20:52:55,887 - ERROR - An uncaught error was raised while processing the update
Traceback (most recent call last):
  File "C:\projects\Movie_bot\env\lib\site-packages\telegram\ext\dispatcher.py", line 279, in process_update
    handler.handle_update(update, self)
  File "C:\projects\Movie_bot\env\lib\site-packages\telegram\ext\conversationhandler.py", line 305, in handle_update
    new_state = self.current_handler.handle_update(update, dispatcher)
  File "C:\projects\Movie_bot\env\lib\site-packages\telegram\ext\regexhandler.py", line 173, in handle_update
    return self.callback(dispatcher.bot, update, **optional_args)
  File "C:\projects\Movie_bot\movie_bot.py", line 62, in get_movie_by_name
    logging.info_movie("User: %s, Chat id: %s, Message: %s",
AttributeError: module 'logging' has no attribute 'info_movie'
2019-01-05 20:52:59,207 - ERROR - An uncaught error was raised while processing the update
Traceback (most recent call last):
  File "C:\projects\Movie_bot\env\lib\site-packages\telegram\ext\dispatcher.py", line 279, in process_update
    handler.handle_update(update, self)
  File "C:\projects\Movie_bot\env\lib\site-packages\telegram\ext\conversationhandler.py", line 305, in handle_update
    new_state = self.current_handler.handle_update(update, dispatcher)
  File "C:\projects\Movie_bot\env\lib\site-packages\telegram\ext\regexhandler.py", line 173, in handle_update
    return self.callback(dispatcher.bot, update, **optional_args)
  File "C:\projects\Movie_bot\movie_bot.py", line 51, in get_actor_by_name
    logging.info_movie("User: %s, Chat id: %s, Message: %s",
AttributeError: module 'logging' has no attribute 'info_movie'
2019-01-05 20:53:54,709 - ERROR - An uncaught error was raised while processing the update
Traceback (most recent call last):
  File "C:\projects\Movie_bot\env\lib\site-packages\telegram\ext\dispatcher.py", line 279, in process_update
    handler.handle_update(update, self)
  File "C:\projects\Movie_bot\env\lib\site-packages\telegram\ext\conversationhandler.py", line 305, in handle_update
    new_state = self.current_handler.handle_update(update, dispatcher)
  File "C:\projects\Movie_bot\env\lib\site-packages\telegram\ext\commandhandler.py", line 173, in handle_update
    return self.callback(dispatcher.bot, update, **optional_args)
  File "C:\projects\Movie_bot\movie_bot.py", line 36, in greet_user
    ['Отмена']
TypeError: list indices must be integers or slices, not str
2019-01-05 20:58:27,667 - WARNING - Retrying (Retry(total=2, connect=None, read=None, redirect=None)) after connection broken by 'ConnectTimeoutError(<telegram.vendor.ptb_urllib3.urllib3.contrib.socks.SOCKSHTTPSConnection object at 0x000000860888CAC8>, 'Connection to api.telegram.org timed out. (connect timeout=5.0)')': /bot689046366:AAFcTW-HmpAkxuTb4a5cOw_sQpdy0XqOxCk/getUpdates
2019-01-05 20:58:42,911 - WARNING - Retrying (Retry(total=1, connect=None, read=None, redirect=None)) after connection broken by 'NewConnectionError('<telegram.vendor.ptb_urllib3.urllib3.contrib.socks.SOCKSHTTPSConnection object at 0x00000086078A96D8>: Failed to establish a new connection: [Errno 11001] getaddrinfo failed',)': /bot689046366:AAFcTW-HmpAkxuTb4a5cOw_sQpdy0XqOxCk/getUpdates
2019-01-05 20:59:34,926 - INFO - Received signal 2 (SIGINT), stopping...
2019-01-05 20:59:43,239 - INFO - Бот запускается
2019-01-05 20:59:47,795 - ERROR - An uncaught error was raised while processing the update
Traceback (most recent call last):
  File "C:\projects\Movie_bot\env\lib\site-packages\telegram\ext\dispatcher.py", line 279, in process_update
    handler.handle_update(update, self)
  File "C:\projects\Movie_bot\env\lib\site-packages\telegram\ext\conversationhandler.py", line 305, in handle_update
    new_state = self.current_handler.handle_update(update, dispatcher)
  File "C:\projects\Movie_bot\env\lib\site-packages\telegram\ext\commandhandler.py", line 173, in handle_update
    return self.callback(dispatcher.bot, update, **optional_args)
  File "C:\projects\Movie_bot\movie_bot.py", line 39, in greet_user
    logging.info_movie("User: %s, Chat id: %s, Message: %s",
AttributeError: module 'logging' has no attribute 'info_movie'
2019-01-05 21:03:57,981 - INFO - Received signal 2 (SIGINT), stopping...
2019-01-05 21:04:06,805 - INFO - Бот запускается
2019-01-05 21:04:12,189 - INFO - User: dm_zakharov, Chat id: 435920381, Message: /start
2019-01-05 21:04:15,420 - INFO - User: dm_zakharov, Chat id: 435920381, Message: Поиск фильма
2019-01-05 21:04:17,575 - INFO - using lxml
2019-01-05 21:04:19,476 - INFO - using lxml html builder
2019-01-05 21:04:19,656 - ERROR - An uncaught error was raised while processing the update
Traceback (most recent call last):
  File "C:\projects\Movie_bot\env\lib\site-packages\telegram\ext\dispatcher.py", line 279, in process_update
    handler.handle_update(update, self)
  File "C:\projects\Movie_bot\env\lib\site-packages\telegram\ext\conversationhandler.py", line 305, in handle_update
    new_state = self.current_handler.handle_update(update, dispatcher)
  File "C:\projects\Movie_bot\env\lib\site-packages\telegram\ext\messagehandler.py", line 169, in handle_update
    return self.callback(dispatcher.bot, update, **optional_args)
  File "C:\projects\Movie_bot\movie_bot.py", line 92, in search_movie
    id_movie = movie[0].movieID
IndexError: list index out of range
2019-01-05 21:04:27,007 - INFO - using lxml html builder
2019-01-05 21:04:30,068 - INFO - using lxml html builder
2019-01-05 21:04:31,951 - INFO - using lxml html builder
2019-01-05 21:04:31,995 - INFO - User: dm_zakharov, Chat id: 435920381, Message: matrix
2019-01-05 21:04:32,570 - INFO - User: dm_zakharov, Chat id: 435920381, Message: Отмена
2019-01-05 21:04:44,791 - INFO - Received signal 2 (SIGINT), stopping...
